[2024-02-20 14:39:15,613: ERROR/MainProcess] Message Error: Couldn't apply scheduled task run-every-five-min: type() missing 1 required positional argument: 'self'
['  File "/home/rehan/PycharmProjects/celeryTaskProject/.venv/bin/celery", line 8, in <module>\n    sys.exit(main())\n', '  File "/home/rehan/PycharmProjects/celeryTaskProject/.venv/lib/python3.10/site-packages/celery/__main__.py", line 15, in main\n    sys.exit(_main())\n', '  File "/home/rehan/PycharmProjects/celeryTaskProject/.venv/lib/python3.10/site-packages/celery/bin/celery.py", line 236, in main\n    return celery(auto_envvar_prefix="CELERY")\n', '  File "/home/rehan/PycharmProjects/celeryTaskProject/.venv/lib/python3.10/site-packages/click/core.py", line 1157, in __call__\n    return self.main(*args, **kwargs)\n', '  File "/home/rehan/PycharmProjects/celeryTaskProject/.venv/lib/python3.10/site-packages/click/core.py", line 1078, in main\n    rv = self.invoke(ctx)\n', '  File "/home/rehan/PycharmProjects/celeryTaskProject/.venv/lib/python3.10/site-packages/click/core.py", line 1688, in invoke\n    return _process_result(sub_ctx.command.invoke(sub_ctx))\n', '  File "/home/rehan/PycharmProjects/celeryTaskProject/.venv/lib/python3.10/site-packages/click/core.py", line 1434, in invoke\n    return ctx.invoke(self.callback, **ctx.params)\n', '  File "/home/rehan/PycharmProjects/celeryTaskProject/.venv/lib/python3.10/site-packages/click/core.py", line 783, in invoke\n    return __callback(*args, **kwargs)\n', '  File "/home/rehan/PycharmProjects/celeryTaskProject/.venv/lib/python3.10/site-packages/click/decorators.py", line 33, in new_func\n    return f(get_current_context(), *args, **kwargs)\n', '  File "/home/rehan/PycharmProjects/celeryTaskProject/.venv/lib/python3.10/site-packages/celery/bin/base.py", line 134, in caller\n    return f(ctx, *args, **kwargs)\n', '  File "/home/rehan/PycharmProjects/celeryTaskProject/.venv/lib/python3.10/site-packages/celery/bin/beat.py", line 72, in beat\n    return beat().run()\n', '  File "/home/rehan/PycharmProjects/celeryTaskProject/.venv/lib/python3.10/site-packages/celery/apps/beat.py", line 84, in run\n    self.start_scheduler()\n', '  File "/home/rehan/PycharmProjects/celeryTaskProject/.venv/lib/python3.10/site-packages/celery/apps/beat.py", line 113, in start_scheduler\n    service.start()\n', '  File "/home/rehan/PycharmProjects/celeryTaskProject/.venv/lib/python3.10/site-packages/celery/beat.py", line 643, in start\n    interval = self.scheduler.tick()\n', '  File "/home/rehan/PycharmProjects/celeryTaskProject/.venv/lib/python3.10/site-packages/celery/beat.py", line 353, in tick\n    self.apply_entry(entry, producer=self.producer)\n', '  File "/home/rehan/PycharmProjects/celeryTaskProject/.venv/lib/python3.10/site-packages/celery/beat.py", line 283, in apply_entry\n    exc, traceback.format_stack(), exc_info=True)\n']
Traceback (most recent call last):
  File "/home/rehan/PycharmProjects/celeryTaskProject/.venv/lib/python3.10/site-packages/celery/beat.py", line 402, in apply_async
    return task.apply_async(entry_args, entry_kwargs,
  File "/home/rehan/PycharmProjects/celeryTaskProject/.venv/lib/python3.10/site-packages/celery/app/task.py", line 559, in apply_async
    check_arguments(*(args or ()), **(kwargs or {}))
TypeError: type() missing 1 required positional argument: 'self'

During handling of the above exception, another exception occurred:

Traceback (most recent call last):
  File "/home/rehan/PycharmProjects/celeryTaskProject/.venv/lib/python3.10/site-packages/celery/beat.py", line 280, in apply_entry
    result = self.apply_async(entry, producer=producer, advance=False)
  File "/home/rehan/PycharmProjects/celeryTaskProject/.venv/lib/python3.10/site-packages/celery/beat.py", line 410, in apply_async
    reraise(SchedulingError, SchedulingError(
  File "/home/rehan/PycharmProjects/celeryTaskProject/.venv/lib/python3.10/site-packages/celery/exceptions.py", line 109, in reraise
    raise value.with_traceback(tb)
  File "/home/rehan/PycharmProjects/celeryTaskProject/.venv/lib/python3.10/site-packages/celery/beat.py", line 402, in apply_async
    return task.apply_async(entry_args, entry_kwargs,
  File "/home/rehan/PycharmProjects/celeryTaskProject/.venv/lib/python3.10/site-packages/celery/app/task.py", line 559, in apply_async
    check_arguments(*(args or ()), **(kwargs or {}))
celery.beat.SchedulingError: Couldn't apply scheduled task run-every-five-min: type() missing 1 required positional argument: 'self'
[2024-02-20 14:39:25,610: ERROR/MainProcess] Message Error: Couldn't apply scheduled task run-every-five-min: type() missing 1 required positional argument: 'self'
['  File "/home/rehan/PycharmProjects/celeryTaskProject/.venv/bin/celery", line 8, in <module>\n    sys.exit(main())\n', '  File "/home/rehan/PycharmProjects/celeryTaskProject/.venv/lib/python3.10/site-packages/celery/__main__.py", line 15, in main\n    sys.exit(_main())\n', '  File "/home/rehan/PycharmProjects/celeryTaskProject/.venv/lib/python3.10/site-packages/celery/bin/celery.py", line 236, in main\n    return celery(auto_envvar_prefix="CELERY")\n', '  File "/home/rehan/PycharmProjects/celeryTaskProject/.venv/lib/python3.10/site-packages/click/core.py", line 1157, in __call__\n    return self.main(*args, **kwargs)\n', '  File "/home/rehan/PycharmProjects/celeryTaskProject/.venv/lib/python3.10/site-packages/click/core.py", line 1078, in main\n    rv = self.invoke(ctx)\n', '  File "/home/rehan/PycharmProjects/celeryTaskProject/.venv/lib/python3.10/site-packages/click/core.py", line 1688, in invoke\n    return _process_result(sub_ctx.command.invoke(sub_ctx))\n', '  File "/home/rehan/PycharmProjects/celeryTaskProject/.venv/lib/python3.10/site-packages/click/core.py", line 1434, in invoke\n    return ctx.invoke(self.callback, **ctx.params)\n', '  File "/home/rehan/PycharmProjects/celeryTaskProject/.venv/lib/python3.10/site-packages/click/core.py", line 783, in invoke\n    return __callback(*args, **kwargs)\n', '  File "/home/rehan/PycharmProjects/celeryTaskProject/.venv/lib/python3.10/site-packages/click/decorators.py", line 33, in new_func\n    return f(get_current_context(), *args, **kwargs)\n', '  File "/home/rehan/PycharmProjects/celeryTaskProject/.venv/lib/python3.10/site-packages/celery/bin/base.py", line 134, in caller\n    return f(ctx, *args, **kwargs)\n', '  File "/home/rehan/PycharmProjects/celeryTaskProject/.venv/lib/python3.10/site-packages/celery/bin/beat.py", line 72, in beat\n    return beat().run()\n', '  File "/home/rehan/PycharmProjects/celeryTaskProject/.venv/lib/python3.10/site-packages/celery/apps/beat.py", line 84, in run\n    self.start_scheduler()\n', '  File "/home/rehan/PycharmProjects/celeryTaskProject/.venv/lib/python3.10/site-packages/celery/apps/beat.py", line 113, in start_scheduler\n    service.start()\n', '  File "/home/rehan/PycharmProjects/celeryTaskProject/.venv/lib/python3.10/site-packages/celery/beat.py", line 643, in start\n    interval = self.scheduler.tick()\n', '  File "/home/rehan/PycharmProjects/celeryTaskProject/.venv/lib/python3.10/site-packages/celery/beat.py", line 353, in tick\n    self.apply_entry(entry, producer=self.producer)\n', '  File "/home/rehan/PycharmProjects/celeryTaskProject/.venv/lib/python3.10/site-packages/celery/beat.py", line 283, in apply_entry\n    exc, traceback.format_stack(), exc_info=True)\n']
Traceback (most recent call last):
  File "/home/rehan/PycharmProjects/celeryTaskProject/.venv/lib/python3.10/site-packages/celery/beat.py", line 402, in apply_async
    return task.apply_async(entry_args, entry_kwargs,
  File "/home/rehan/PycharmProjects/celeryTaskProject/.venv/lib/python3.10/site-packages/celery/app/task.py", line 559, in apply_async
    check_arguments(*(args or ()), **(kwargs or {}))
TypeError: type() missing 1 required positional argument: 'self'

During handling of the above exception, another exception occurred:

Traceback (most recent call last):
  File "/home/rehan/PycharmProjects/celeryTaskProject/.venv/lib/python3.10/site-packages/celery/beat.py", line 280, in apply_entry
    result = self.apply_async(entry, producer=producer, advance=False)
  File "/home/rehan/PycharmProjects/celeryTaskProject/.venv/lib/python3.10/site-packages/celery/beat.py", line 410, in apply_async
    reraise(SchedulingError, SchedulingError(
  File "/home/rehan/PycharmProjects/celeryTaskProject/.venv/lib/python3.10/site-packages/celery/exceptions.py", line 109, in reraise
    raise value.with_traceback(tb)
  File "/home/rehan/PycharmProjects/celeryTaskProject/.venv/lib/python3.10/site-packages/celery/beat.py", line 402, in apply_async
    return task.apply_async(entry_args, entry_kwargs,
  File "/home/rehan/PycharmProjects/celeryTaskProject/.venv/lib/python3.10/site-packages/celery/app/task.py", line 559, in apply_async
    check_arguments(*(args or ()), **(kwargs or {}))
celery.beat.SchedulingError: Couldn't apply scheduled task run-every-five-min: type() missing 1 required positional argument: 'self'
